2025-02-25 17:04:59,996 ERROR: Exception on /auth/login [GET] [in C:\Users\miilo\Desktop\fitness-tracker\venv\Lib\site-packages\flask\app.py:875]
Traceback (most recent call last):
  File "C:\Users\miilo\Desktop\fitness-tracker\venv\Lib\site-packages\flask\app.py", line 1511, in wsgi_app
    response = self.full_dispatch_request()
               ^^^^^^^^^^^^^^^^^^^^^^^^^^^^
  File "C:\Users\miilo\Desktop\fitness-tracker\venv\Lib\site-packages\flask\app.py", line 919, in full_dispatch_request
    rv = self.handle_user_exception(e)
         ^^^^^^^^^^^^^^^^^^^^^^^^^^^^^
  File "C:\Users\miilo\Desktop\fitness-tracker\venv\Lib\site-packages\flask\app.py", line 917, in full_dispatch_request
    rv = self.dispatch_request()
         ^^^^^^^^^^^^^^^^^^^^^^^
  File "C:\Users\miilo\Desktop\fitness-tracker\venv\Lib\site-packages\flask\app.py", line 902, in dispatch_request
    return self.ensure_sync(self.view_functions[rule.endpoint])(**view_args)  # type: ignore[no-any-return]
           ^^^^^^^^^^^^^^^^^^^^^^^^^^^^^^^^^^^^^^^^^^^^^^^^^^^^^^^^^^^^^^^^^
  File "C:\Users\miilo\Desktop\fitness-tracker\app\auth\routes.py", line 34, in login
    return render_template('auth/login.html', title='Sign In', form=form)
           ^^^^^^^^^^^^^^^^^^^^^^^^^^^^^^^^^^^^^^^^^^^^^^^^^^^^^^^^^^^^^^
  File "C:\Users\miilo\Desktop\fitness-tracker\venv\Lib\site-packages\flask\templating.py", line 150, in render_template
    return _render(app, template, context)
           ^^^^^^^^^^^^^^^^^^^^^^^^^^^^^^^
  File "C:\Users\miilo\Desktop\fitness-tracker\venv\Lib\site-packages\flask\templating.py", line 131, in _render
    rv = template.render(context)
         ^^^^^^^^^^^^^^^^^^^^^^^^
  File "C:\Users\miilo\Desktop\fitness-tracker\venv\Lib\site-packages\jinja2\environment.py", line 1295, in render
    self.environment.handle_exception()
  File "C:\Users\miilo\Desktop\fitness-tracker\venv\Lib\site-packages\jinja2\environment.py", line 942, in handle_exception
    raise rewrite_traceback_stack(source=source)
  File "C:\Users\miilo\Desktop\fitness-tracker\app\templates\auth\login.html", line 2, in top-level template code
    {% import "bootstrap_wtf.html" as wtf %}
    ^^^^^^^^^^^^^^^^^^^^^^^^^
  File "C:\Users\miilo\Desktop\fitness-tracker\app\templates\base.html", line 60, in top-level template code
    {% block content %}{% endblock %}
    ^^^^^^^^^^^^^^^^^^^^^^^^^
  File "C:\Users\miilo\Desktop\fitness-tracker\app\templates\auth\login.html", line 6, in block 'content'
    {{ wtf.quick_form(form) }}
    ^^^^^^^^^^^^^^^^^^^^^^^^^
  File "C:\Users\miilo\Desktop\fitness-tracker\venv\Lib\site-packages\jinja2\runtime.py", line 784, in _invoke
    rv = self._func(*arguments)
         ^^^^^^^^^^^^^^^^^^^^^^
  File "C:\Users\miilo\Desktop\fitness-tracker\app\templates\bootstrap_wtf.html", line 73, in template
    {{ form_field(field, ns.first_field, autocomplete_map.get(field.name)) }}
    ^^^^^^^^^^^^^^^^^^^^^^^^^
TypeError: macro 'form_field' takes not more than 2 argument(s)
2025-02-25 17:08:41,000 INFO: Fitness Tracker startup [in C:\Users\miilo\Desktop\fitness-tracker\app\__init__.py:49]
